2024-06-28 11:21:58,903 - FILE201.Database_Connection.DBConnection - ERROR - Error while connecting to MySQL: 2003 (HY000): Can't connect to MySQL server on 'localhost:3306' (10061)
Traceback (most recent call last):
  File "C:\Users\Maze\AppData\Local\Programs\Python\Python39\lib\site-packages\mysql\connector\connection_cext.py", line 327, in _open_connection
    self._cmysql.connect(**cnx_kwargs)
_mysql_connector.MySQLInterfaceError: Can't connect to MySQL server on 'localhost:3306' (10061)

The above exception was the direct cause of the following exception:

Traceback (most recent call last):
  File "F:\2024 Python Lesson\systemPayroll\FILE201\Database_Connection\DBConnection.py", line 25, in create_connection
    connection = mysql.connector.connect(
  File "C:\Users\Maze\AppData\Local\Programs\Python\Python39\lib\site-packages\mysql\connector\pooling.py", line 322, in connect
    return CMySQLConnection(*args, **kwargs)
  File "C:\Users\Maze\AppData\Local\Programs\Python\Python39\lib\site-packages\mysql\connector\connection_cext.py", line 144, in __init__
    self.connect(**kwargs)
  File "C:\Users\Maze\AppData\Local\Programs\Python\Python39\lib\site-packages\mysql\connector\abstracts.py", line 1360, in connect
    self._open_connection()
  File "C:\Users\Maze\AppData\Local\Programs\Python\Python39\lib\site-packages\mysql\connector\connection_cext.py", line 332, in _open_connection
    raise get_mysql_exception(
mysql.connector.errors.DatabaseError: 2003 (HY000): Can't connect to MySQL server on 'localhost:3306' (10061)
2024-06-28 11:21:58,978 - FILE201.Database_Connection.listSQLQuery - ERROR - Error: Could not establish database connection.
